# 错误处理

---

## 什么是错误处理

不管你多么精通编程，有时我们的脚本总还是会出现错误。可能是因为我们的编写出错，或是与预期不同的用户输入，或是错误的服务端响应以及其他数千种原因。

通常，如果发生错误，脚本就会“死亡”（立即停止），并在控制台将错误打印出来。

但是有一种语法结构 `try..catch`，它使我们可以“捕获（catch）”错误，因此脚本可以执行更合理的操作，而不是死掉。

---

## `try…catch`语法

`try..catch` 结构由两部分组成：`try` 和 `catch`：

```javascript
try {
  // 代码...
} catch (err) {
  // 错误捕获
}
```

===

### 执行步骤

它按照以下步骤执行：

1. 首先，执行 `try {...}` 中的代码。
2. 如果这里没有错误，则忽略 `catch(err)`：执行到 `try` 的末尾并跳过 `catch` 继续执行。
3. 如果这里出现错误，则 `try` 执行停止，控制流转向 `catch(err)` 的开头。变量 `err`（我们可以使用任何名称）将包含一个 error 对象，该对象包含了所发生事件的详细信息。

所以，`try {…}` 块内的错误不会杀死脚本 — 我们有机会在 `catch` 中处理它。

===

### 例子

- 没有 error 的例子：显示 `console.log` `(1)` 和 `(2)`：

  ```javascript
  try {
    console.log('Start of try runs');  // (1) <--
    // ...这里没有 error
    console.log('End of try runs');   // (2) <--
  } catch(err) {
    console.log('Catch is ignored, because there are no errors'); // (3)
  }
  ```

- 包含 error 的例子：显示 `(1)` 和 `(3)` 行的 `console.log` 中的内容：

  ```javascript
  try {
    console.log('Start of try runs');  // (1) <--
    lalala; // Error，变量未定义！
    console.log('End of try (never reached)');  // (2)
  } catch(err) {
    console.log(`Error has occurred!`); // (3) <--
  }
  ```

===

### 代码必须是可执行

`try..catch` 仅对运行时的 error 有效

要使得 `try..catch` 能工作，代码必须是可执行的。换句话说，它必须是有效的 JavaScript 代码。

如果代码包含语法错误，那么 `try..catch` 将无法正常工作，例如含有不匹配的花括号：

```javascript
try {
  {{{{{{{{{{{{
} catch(e) {
  console.log("The engine can't understand this code, it's invalid");
}
```

JavaScript 引擎首先会读取代码，然后运行它。在读取阶段发生的错误被称为“解析时间（parse-time）”错误，并且无法恢复（从该代码内部）。这是因为引擎无法理解该代码。

所以，`try..catch` 只能处理有效代码中出现的错误。这类错误被称为“运行时的错误（runtime errors）”，有时被称为“异常（exceptions）”。

===

### 代码运行必须是同步的

在 `setTimeout` 中，则 `try..catch` 不会捕获到异常：

```javascript
try {
  setTimeout(function() {
    noSuchVariable; // 脚本将在这里停止运行
  }, 1000);
} catch (e) {
  console.log( "won't work" );
}
```

函数本身要稍后才执行，这时引擎已经离开了 `try..catch` 结构。为了捕获到计划的（scheduled）函数中的异常，那么 `try..catch` 必须在这个函数内：

```javascript
setTimeout(function() {
  try {
    noSuchVariable; // try..catch 处理 error 了！
  } catch {
    console.log( "error is caught here!" );
  }
}, 1000);
```

---

## `Error` 对象

发生错误时，JavaScript 生成一个包含有关其详细信息的对象。然后将该对象作为参数传递给 `catch`：

```javascript
try {
  // ...
} catch(err) { // <-- “error 对象”，也可以用其他参数名代替 err
  // ...
}
```

===

### `error`对象的属性

对于所有内建的 error，error 对象具有两个主要属性：

- `name` Error 名称。例如，对于一个未定义的变量，名称是 `"ReferenceError"`。
- `message` 关于 error 的详细文字描述。

例子

```javascript
try {
  lalala; // error, variable is not defined!
} catch(err) {
  console.log(err.name); // ReferenceError
  console.log(err.message); // lalala is not defined
  console.log(err.stack); // ReferenceError: lalala is not defined at (...call stack)

  // 也可以将一个 error 作为整体显示出来as a whole
  // Error 信息被转换为像 "name: message" 这样的字符串
  console.log(err); // ReferenceError: lalala is not defined
}
```

---

## `try…catch` 使用

**如果 `json` 格式错误，`JSON.parse` 就会生成一个 error，因此脚本就会“死亡”。**

让我们用 `try..catch` 来处理这个 error：

```javascript
let json = "{ bad json }";

try {
  let user = JSON.parse(json); // <-- 当出现一个 error 时...
  console.log( user.name ); // 不工作
} catch (e) {
  // ...执行会跳转到这里并继续执行
  console.log( "Our apologies, the data has errors, we'll try to request it one more time." );
  console.log( e.name );
  console.log( e.message );
}
```

---

## 抛出内建错误

如果这个 `json` 在语法上是正确的，但是没有所必须的 `name` 属性该怎么办？

```javascript
let json = '{ "age": 30 }'; // 不完整的数据
try {
  let user = JSON.parse(json); // <-- 没有 error
  console.log( user.name ); // 没有 name！
} catch (e) {
  console.log( "doesn't execute" );
}
```

这里 `JSON.parse` 正常执行，但是缺少 `name` 属性对我们来说确实是个 error。为了统一进行 error 处理，我们将使用 `throw` 操作符。

---

## `Throw` 操作符

`throw` 操作符会生成一个 error 对象。

语法如下：

```javascript
throw error object
```

===

## `error` 的构造器

技术上讲，我们可以将任何东西用作 error 对象。甚至可以是一个原始类型数据，例如数字或字符串，但最好使用对象，最好使用具有 `name` 和 `message` 属性的对象（某种程度上保持与内建 error 的兼容性）。

JavaScript 中有很多内建的标准 error 的构造器：`Error`，`SyntaxError`，`ReferenceError`，`TypeError` 等。我们也可以使用它们来创建 error 对象。

它们的语法是：

```javascript
let error = new Error(message);
// 或
let error = new SyntaxError(message);
let error = new ReferenceError(message);
// ...
```

===

### 内建 `error`

对于内建的 error，`name` 属性刚好就是构造器的名字。`message` 则来自于参数。

```javascript
let error = new Error("Things happen o_O");
console.log(error.name); // Error
console.log(error.message); // Things happen o_O
```

 `JSON.parse` 会生成什么样的 error：

```javascript
try {
  JSON.parse("{ bad json o_O }");
} catch(e) {
  console.log(e.name); // SyntaxError
  console.log(e.message); // Unexpected token b in JSON at position 2
}
```

正如我们所看到的， 那是一个 `SyntaxError`。

在我们的示例中，缺少 `name` 属性就是一个 error，因为用户必须有一个 `name`。

===

### 抛出 `error`

```javascript
let json = '{ "age": 30 }'; // 不完整的数据
try {
  let user = JSON.parse(json); // <-- 没有 error
  if (!user.name) {
    throw new SyntaxError("Incomplete data: no name"); // (*)
  }
  console.log( user.name );
} catch(e) {
  console.log( "JSON Error: " + e.message );
}
```

在 `(*)` 标记的这一行，`throw` 操作符生成了包含着我们所给定的 `message` 的 `SyntaxError`，与 JavaScript 自己生成的方式相同。`try` 的执行立即停止，控制流转向 `catch` 块。现在，`catch` 成为了所有 error 处理的唯一场所：对于 `JSON.parse` 和其他情况都适用。

---

## 再次抛出

在 `try {...}` 块中是否可能预料之外的 error？例如未定义变量

```javascript
let json = '{ "age": 30 }'; // 不完整的数据
try {
  user = JSON.parse(json); // <-- 忘记在 user 前放置 "let"
  // ...
} catch(err) {
  console.log("JSON Error: " + err); // JSON Error: ReferenceError: user is not defined
  // (实际上并没有 JSON Error)
}
```

catch 会捕获到 **所有** 来自于 `try` 的 error。这里，捕获到了一个预料之外的 error，但是仍然抛出的是同样的 `"JSON Error"` 信息。这是不正确的，并且也会使代码变得更难以调试。

===

### 错误的判断

我们可以通过其他方式找出我们捕获的是什么 error，例如通过它的 `name` 属性：

```javascript
try {
  user = { /*...*/ };
} catch(e) {
  console.log(e.name); // "ReferenceError" for accessing an undefined variable
}
```

规则：

**`catch` 应该只处理它知道的 error，并“抛出”所有其他 error。**

“再次抛出（rethrowing）”技术可以被更详细地解释为：

1. Catch 捕获所有 error。
2. 在 `catch(err) {...}` 块中，我们对 error 对象 `err` 进行分析。
3. 如果我们不知道如何处理它，那我们就 `throw err`。

===

### 例`1`

在下面的代码中，我们使用“再次抛出”，在 `catch` 中只处理 `SyntaxError` 

```javascript
let json = '{ "age": 30 }'; // 不完整的数据
try {
  let user = JSON.parse(json);
  if (!user.name) {
    throw new SyntaxError("Incomplete data: no name");
  }
  blabla(); // 预料之外的 error
} catch(e) {
  if (e.name == "SyntaxError") {
    console.log( "JSON Error: " + e.message );
  } else {
    throw e; // 再次抛出 (*)
  }
}
```

如果 `(*)` 标记的这行 `catch` 块中的 error 从 `try..catch` 中“掉了出来”，那么它也可以被外部的 `try..catch` 结构（如果存在）捕获到，如果外部不存在这种结构，那么脚本就会被杀死。

===

### 例`2`

下面这个示例演示了这种类型的 error 是如何被另外一级 `try..catch` 捕获的：

```javascript
function readData() {
  let json = '{ "age": 30 }';
  try {  
    blabla(); /*error!*/ 
  } catch (e) {
    if (e.name != 'SyntaxError') {
      throw e; // 再次抛出（不知道如何处理它）
    }
  }
}
try { readData(); } catch (e) {
  console.log( "External catch got: " + e ); // 捕获了它！
}
```

上面这个例子中的 `readData` 只知道如何处理 `SyntaxError`，而外部的 `try..catch` 知道如何处理任意的 error。

---

## `try…catch…finally`

`try..catch` 结构可能还有一个代码子句（clause）：`finally`。

如果它存在，它在所有情况下都会被执行：

- `try` 之后，如果没有 error，
- `catch` 之后，如果没有 error。

语法：

```javascript
try {
   ... 尝试执行的代码 ...
} catch(e) {
   ... 处理 error ...
} finally {
   ... 总是会执行的代码 ...
}
```

===

### 例子

```javascript
try {
  blabla(); /*error!*/ 
} catch (e) {
  console.log( 'catch' );
} finally {
  console.log( 'finally' );
}
```

这段代码有两种执行方式：

1. 如果 `blabla()` 未定义，那么执行 `try -> catch -> finally`。
2. 如果 `blabla()` 已定义，那么执行 `try -> finally`。

`finally` 子句（clause）通常用在这种情况下使用：当我们开始做某事的时候，希望无论出现什么情况都要完成完成某个任务。

---

### `finally` 和 `return`

在下面这个例子中，在 `try` 中有一个 `return`。在这种情况下，`finally` 会在控制转向外部代码前被执行。

```javascript
function func() {

  try {
    return 1;

  } catch (e) {
    /* ... */
  } finally {
    console.log( 'finally' );
  }
}

console.log( func() ); // 先执行 finally 中的 console.log，然后执行这个 console.log
```

===

### `try..finally`

没有 `catch` 子句的 `try..finally` 结构也很有用。

```javascript
function func() {
  // 开始执行需要被完成的操作（比如测量）
  try {
    // ...
  } finally {
    // 完成前面我们需要完成的那件事儿，即使 try 中的执行失败了
  }
}
```

上面的代码中，由于没有 `catch`，所以 `try` 中的 error 总是会使代码执行跳转至函数 `func()` 外。但是，在跳出之前需要执行 `finally` 中的代码。

---

## 全局 `catch`

 [window.onerror](https://developer.mozilla.org/zh/docs/Web/API/GlobalEventHandlers/onerror) 事件属性，该函数将在发生未捕获的 error 时执行。

```javascript
window.onerror = function(message, url, line, col, error) {
  // ...
};
```

- `message`Error 信息。
- `url`发生 error 的脚本的 URL。
- `line`，`col`发生 error 处的代码的行号和列号。
- `error`Error 对象。

```javascript
window.onerror = function(message, url, line, col, error) {
  console.log(`${message}\n At ${line}:${col} of ${url}`);
};
function readData() {
  badFunc(); // 啊，出问题了！
}
readData();
```

全局错误处理程序 `window.onerror` 的作用通常不是恢复脚本的执行 — 它的作用是将错误信息发送给开发者。

---

## 总结

### 语法

`try..catch` 结构允许我们处理执行过程中出现的 error。从字面上看，它允许“尝试”运行代码并“捕获”其中可能发生的错误。

```javascript
try {
  // 执行此处代码
} catch(err) {
  // 如果发生错误，跳转至此处
  // err 是一个 error 对象
} finally {
  // 无论怎样都会在 try/catch 之后执行
}
```

这儿可能会没有 `catch` 部分或者没有 `finally`，所以 `try..catch` 或 `try..finally` 都是可用的。

===

### 属性

Error 对象包含下列属性：

- `message` — 人类可读的 error 信息。
- `name` — 具有 error 名称的字符串（Error 构造器的名称）。
- `stack`（没有标准，但得到了很好的支持）— Error 发生时的调用栈。

===

### 其他

1. 可以使用 `throw` 操作符来生成自定义的 error。从技术上讲，`throw` 的参数可以是任何东西，但通常是继承自内建的 `Error` 类的 error 对象。下一章我们会详细介绍扩展 error。
2. 再次抛出（rethrowing）是一种错误处理的重要模式：`catch` 块通常期望并知道如何处理特定的 error 类型，因此它应该再次抛出它不知道的 error。
3. 即使我们没有 `try..catch`，大多数执行环境也允许我们设置“全局”错误处理程序来捕获“掉出（fall out）”的 error。在浏览器中，就是 `window.onerror`。

---

## 练习

===

### 使用 `finally` 还是直接放在代码后面？

比较下面两个代码片段。

1. 第一个代码片段，使用 `finally` 在 `try..catch` 之后执行代码：

   ```javascript
   try {
   } catch (e) {
   } finally {
     console.log('hello')
   }
   ```

2. 第二个代码片段，将`console.log('hello')`代码放在了 `try..catch` 之后：

   ```javascript
   try {
   } catch (e) {
   }
   console.log('hello')
   ```

两段代码又什么不一样，还是两个代码片段效果一样？请举例说明。

